<!DOCTYPE html>
<html lang="en">
<head>
    <meta charset="UTF-8">
    <meta name="viewport" content="width=device-width, initial-scale=1.0">
    <meta http-equiv="X-UA-Compatible" content="ie=edge">
    <title>Promise Es6</title>
</head>
<body>
    <!-- <h2>每5行一个知识点</h2> -->
    <script>
        // 每个间隔 5 行一个知识点

        // Promise.reject(Promise.reject(Promise.reject(Promise.reject(Promise.reject(Promise.resolve())))))
        //  .catch(()=>{console.log(99)}).catch(()=>{console.log(100)}).then(()=>{console.log(101)})

        // Promise.resolve(Promise.reject(Promise.resolve(Promise.resolve(Promise.resolve(Promise.reject())))))
        //     .catch(()=>{console.log(99)}).catch(()=>{console.log(100)}).then(()=>{console.log(101)})

        // const p1 = new Promise((resolve,reject)=>{
        //     setTimeout(()=>{
        //         reject(1)
        //     },1000)
        // })
        //     // .then((res)=>{
        //     // console.log('then p1',res)
        //     // }).catch((res)=>{
        //     //     console.log('catch p1',res)
        //     // })

        // const p2 = new Promise((resolve,reject)=>{
        //     // 当 Promise1 对象返回另一个 Promise2 对象时，自己（Promise1）的状态失效，使用传入的另外一个的 Promise2 状态。
        //     // 如果 Promise1 是 pending 状态那么会等待（Promise1）的状态改变后执行（Promise2）的回调函数
        //     setTimeout(()=>{
        //         resolve(p1)
        //     },3000)
        // })

        // const p3 = new Promise((resolve,reject)=>{
        //     // 没有回调的 Promise 对象会在控制台报错 "Promise.html:30 Uncaught (in promise)"
        //     reject('99')
        // })

        // p2
        //     .then((res)=>{
        //         console.log('then p2',res)
        //     }).catch((res)=>{
        //         console.log('catch p2',res)
        //         console.log(p2)
        //     }).then(()=>{
        //         console.log('content then');
        //         console.log(p2);
        //     }).catch((res)=>{
        //         console.log('content catch');
        //         console.log(p2)
        //     })





        // // .then() 方法必定返回一个 Promise.resolve() 的实例对象。
        // // 并且将 .then(function) 中的 function 的返回值（res）作为参数传入 Promise.resolve(res)。
        // const p4 = new Promise((resolve,reject)=>{
        //                 resolve(1)
        //             }).then((res)=>{
        //                 // console.log(res)
        //                 return  new Promise((resolve,reject)=>{
        //                             reject(res);
        //                         });
        //             }).then((res)=>{
        //                 console.log(res,"dui")
        //                 return res;
        //             },(res)=>{
        //                 console.log(res,"err")
        //                 return new Promise((resolve,reject)=>{
        //                             reject(res);
        //                         });
        //             })
        // setTimeout(()=>{
        //     console.log(p4,"这里是p4")
        // },10000)
        // // 证明 (发现：如果Promise中执行时报错 执行 reject() ，两个不存在的 res 变量)
        // Promise.resolve(new Promise((resolve,reject)=>{
        //     // console.log("-.-",res)
        //     resolve();
        //     // console.log("-.-",res)
        // })).then(()=>{
        //         console.log("p4证明 resolve")
        //     },()=>{
        //         console.log("p4证明 reject")
        //     })






        // Promise.prototype.catch() ，catch方法；
        // .catch() 的返回和 .then() 的返回 处理是一样的 Promise.resolve(res)；
        // 且当 .then() 前的 Promise 对象时 reject 状态时 将来直接跳过这个 .then(function) 中的function执行;
        // Promise 代码执行报错不会 影响 到外部代码执行
        // const p5 = new Promise((resolve,reject)=>{
        //     setTimeout(()=>{
        //         reject("p5 reject")
        //         // resolve("p5 resolve")
        //     },3000)
        // }).then((res)=>{
        //     console.log(res);
        //     return res
        // }).then((res)=>{
        //     console.log(res);
        // }
        //     ,(res)=>{
        //         console.log("拦截Catch")
        //         // return Promise.reject();
        //     }
        // ).then((res)=>{
        //     console.log("拦截then")
        // }).catch((res)=>{
        //     console.log(res)
        //     return Promise.reject();
        // }).then((res)=>{
        //     console.log(res,1)
        // }).catch((res)=>{
        //     console.log(res,2)
        // })

        // 总结：.then(function) 前方 Promise 代码不报错，执行传入的 function 返回 Promise.resolve(res)
        //                                   代码报错，（报错后，function 默认返回reject状态的 Promise）直接返回 Promise.resolve(res) （包裹前一个Promise对象）;
        //       .catch(function) 前方 Promise 代码报错，执行传入的 function 返回 Promise.resolve(res) （并取消前面的报错）;
        //                                     代码不报错，将直接返回 Promise.resolve(res) 这个res是前一个.then() 或 .catch() 执行后的返回值;      
        //         Promise.resolve(Promise) 当Promise.resolve()传入一个 Promise 对象时他后面的回调函数根据传入的Promise状态来改变来执行后续回调;
        // 注：res 为每个传入的 function 的 return 值   
        // 例：
        // const p6 = Promise.resolve(Promise.reject())

        // p6.then(()=>{
        //         console.log("then");
        //         console.log(p6)
        //     }).catch(()=>{
        //         console.log("catch")
        //         console.log(p6)
        //     })






        // // Promise.prototype.finally();
        // Promise.resolve().then(()=>{
        //     console.log("then")
        // }).catch(()=>{
        //     console.log("catch")
        // }).finally(()=>{
        //     console.log("都执行")
        // })
        // // finally方法总是会返回原来的值;
        // // resolve 的值是 undefined
        // Promise.resolve(2).then(() => {}, () => {})

        // // resolve 的值是 2
        // Promise.resolve(2).finally(() => {})

        // // reject 的值是 undefined
        // Promise.reject(3).then(() => {}, () => {})

        // // reject 的值是 3
        // Promise.reject(3).finally(() => {})






        // Promise.all方法的参数可以不是数组，但必须具有 Iterator 接口，且返回的每个成员都是 Promise 实例;
        // 当每一项不是 Promise 对象时，会进行封装后返回;
        // 所有参数其中一个 rejected 状态后，Promise.all 的状态就变成rejected，此时第一个被reject的实例的返回值，会传递给 Promise.all 的回调函数;
        // 所有参数变成 resolve 状态后，Promise.all 的状态就变成 resolve，此时所有参数的范湖值组成一个数组，传递给 Promise.all 的回调函数;

        // 例：Promise.all([p1,p2,p3,p4])

        // Promise.race()方法;
        // Promise.race中那一项最先转变状态 就使用那一项的状态，和返回值;

        // 例：Promise.race([p1,p2,p3,p4])


        // const pp1 = new Promise((resolve,reject)=>{
        //             setTimeout(()=>{
        //                 resolve('data1')
        //             },2000)
        //         })
        // const pp2 = new Promise((resolve,reject)=>{
        //             setTimeout(()=>{
        //                 resolve('data2')
        //             },1000)
        //         })
        // const pp3 = new Promise((resolve,reject)=>{
        //             setTimeout(()=>{
        //                 reject('data3')
        //             },3000)
        //         })
        // setTimeout(()=>{
        //     console.log(Promise.resolve(pp1),pp2,Promise.resolve(pp3))
        // },5000)

        //  Promise 中出现错误，.then(function)不在触发function 直接返回触发这个的 Promise 对象（或 Promise.resolve(res) 猜测），
        // 只需用 catch 解决一次，后边再也不会因为这个错误而再触发 catch了，.then() 就可以开始正常触发了。
    </script>                       
</body>
</html>